Workbook

Sheet Knockout Matches
A1: id | B1: Match | C1: Round | D1: Name 1 | E1: Club 1 | F1: Score 1 | G1: Name 2 | H1: Club 2 | I1: Score 2
A2: 1 | B2: 1 | C2: 32 | D2: {='Knockout Grid'!A2:C2} -> G1W | E2: 0 | F2: 0 | G2: {='Knockout Grid'!A3:C3} -> bye | H2: 0 | I2: 0
A3: 2 | B3: 2 | C3: 32 | D3: {='Knockout Grid'!A6:C6} -> Player 3 | E3: 0 | F3: 0 | G3: {='Knockout Grid'!A7:C7} -> Player 4 | H3: 0 | I3: 0
A4: 3 | B4: 3 | C4: 32 | D4: {='Knockout Grid'!A10:C10} -> Player 5 | E4: 0 | F4: 0 | G4: {='Knockout Grid'!A11:C11} -> Player 6 | H4: 0 | I4: 0
A5: 4 | B5: 4 | C5: 32 | D5: {='Knockout Grid'!A14:C14} -> Player 7 | E5: 0 | F5: 0 | G5: {='Knockout Grid'!A15:C15} -> Player 8 | H5: 0 | I5: 0
A6: 5 | B6: 5 | C6: 32 | D6: {='Knockout Grid'!A18:C18} -> Player 9 | E6: 0 | F6: 0 | G6: {='Knockout Grid'!A19:C19} -> Player 10 | H6: 0 | I6: 0
A7: 6 | B7: 6 | C7: 32 | D7: {='Knockout Grid'!A22:C22} -> Player 11 | E7: 0 | F7: 0 | G7: {='Knockout Grid'!A23:C23} -> Player 12 | H7: 0 | I7: 0
A8: 7 | B8: 7 | C8: 32 | D8: {='Knockout Grid'!A26:C26} -> Player 13 | E8: 0 | F8: 0 | G8: {='Knockout Grid'!A27:C27} -> Player 14 | H8: 0 | I8: 0
A9: 8 | B9: 8 | C9: 32 | D9: {='Knockout Grid'!A30:C30} -> bye | E9: 0 | F9: 0 | G9: {='Knockout Grid'!A31:C31} -> Player 16 | H9: 0 | I9: 0
A10: 9 | B10: 9 | C10: 32 | D10: {='Knockout Grid'!A34:C34} -> Player 17 | E10: 0 | F10: 0 | G10: {='Knockout Grid'!A35:C35} -> bye | H10: 0 | I10: 0
A11: 10 | B11: 10 | C11: 32 | D11: {='Knockout Grid'!A38:C38} -> Player 19 | E11: 0 | F11: 0 | G11: {='Knockout Grid'!A39:C39} -> Player 20 | H11: 0 | I11: 0
A12: 11 | B12: 11 | C12: 32 | D12: {='Knockout Grid'!A42:C42} -> Player 21 | E12: 0 | F12: 0 | G12: {='Knockout Grid'!A43:C43} -> Player 22 | H12: 0 | I12: 0
A13: 12 | B13: 12 | C13: 32 | D13: {='Knockout Grid'!A46:C46} -> Player 23 | E13: 0 | F13: 0 | G13: {='Knockout Grid'!A47:C47} -> Player 24 | H13: 0 | I13: 0
A14: 13 | B14: 13 | C14: 32 | D14: {='Knockout Grid'!A50:C50} -> Player25 | E14: 0 | F14: 0 | G14: {='Knockout Grid'!A51:C51} -> Player 26 | H14: 0 | I14: 0
A15: 14 | B15: 14 | C15: 32 | D15: {='Knockout Grid'!A54:C54} -> Player 27 | E15: 0 | F15: 0 | G15: {='Knockout Grid'!A55:C55} -> Player 28 | H15: 0 | I15: 0
A16: 15 | B16: 15 | C16: 32 | D16: {='Knockout Grid'!A58:C58} -> Player 29 | E16: 0 | F16: 0 | G16: {='Knockout Grid'!A59:C59} -> Player 30 | H16: 0 | I16: 0
A17: 16 | B17: 16 | C17: 32 | D17: {='Knockout Grid'!A62:C62} -> Bye | E17: 0 | F17: 0 | G17: {='Knockout Grid'!A63:C63} -> G2W | H17: 0 | I17: 0
A18: 17 | B18: 1 | C18: 16 | D18: {='Knockout Grid'!F4:H4} -> G1W | E18: 0 | F18: 0 | G18: {='Knockout Grid'!F5:H5} -> Player 4 | H18: 0 | I18: 0
A19: 18 | B19: 2 | C19: 16 | D19: {='Knockout Grid'!F12:H12} -> Player 5 | E19: 0 | F19: 0 | G19: {='Knockout Grid'!F13:H13} -> Player 8 | H19: 0 | I19: 0
A20: 19 | B20: 3 | C20: 16 | D20: {='Knockout Grid'!F20:H20} -> Player 9 | E20: 0 | F20: 0 | G20: {='Knockout Grid'!F21:H21} -> Player 12 | H20: 0 | I20: 0
A21: 20 | B21: 4 | C21: 16 | D21: {='Knockout Grid'!F28:H28} -> Player 13 | E21: 0 | F21: 0 | G21: {='Knockout Grid'!F29:H29} -> Player 16 | H21: 0 | I21: 0
A22: 21 | B22: 5 | C22: 16 | D22: {='Knockout Grid'!F36:H36} -> Player 17 | E22: 0 | F22: 0 | G22: {='Knockout Grid'!F37:H37} -> Player 20 | H22: 0 | I22: 0
A23: 22 | B23: 6 | C23: 16 | D23: {='Knockout Grid'!F44:H44} -> Player 21 | E23: 0 | F23: 0 | G23: {='Knockout Grid'!F45:H45} -> Player 24 | H23: 0 | I23: 0
A24: 23 | B24: 7 | C24: 16 | D24: {='Knockout Grid'!F52:H52} -> Player25 | E24: 0 | F24: 0 | G24: {='Knockout Grid'!F53:H53} -> Player 28 | H24: 0 | I24: 0
A25: 24 | B25: 8 | C25: 16 | D25: {='Knockout Grid'!F60:H60} -> Player 29 | E25: 0 | F25: 0 | G25: {='Knockout Grid'!F61:H61} -> G2W | H25: 0 | I25: 0
A26: 25 | B26: 1 | C26: Q | D26: {='Knockout Grid'!K8:M8} -> Player 1 | E26: 0 | F26: 0 | G26: {='Knockout Grid'!K9:M9} -> Player 8 | H26: 0 | I26: 0
A27: 26 | B27: 2 | C27: Q | D27: {='Knockout Grid'!K24:M24} -> Player 9 | E27: 0 | F27: 0 | G27: {='Knockout Grid'!K25:M25} -> Player 16 | H27: 0 | I27: 0
A28: 27 | B28: 3 | C28: Q | D28: {='Knockout Grid'!K40:M40} -> Player 17 | E28: 0 | F28: 0 | G28: {='Knockout Grid'!K41:M41} -> Player 24 | H28: 0 | I28: 0
A29: 28 | B29: 4 | C29: Q | D29: {='Knockout Grid'!K56:M56} -> Player25 | E29: 0 | F29: 0 | G29: {='Knockout Grid'!K57:M57} -> Player 32 | H29: 0 | I29: 0
A30: 29 | B30: 1 | C30: S | D30: {='Knockout Grid'!P16:R16} -> Player 1 | E30: 0 | F30: 0 | G30: {='Knockout Grid'!P17:R17} -> Player 16 | H30: 0 | I30: 0
A31: 30 | B31: 2 | C31: S | D31: {='Knockout Grid'!P48:R48} -> Player 17 | E31: 0 | F31: 0 | G31: {='Knockout Grid'!P49:R49} -> Player 32 | H31: 0 | I31: 0
A32: 31 | B32: 1 | C32: F | D32: {='Knockout Grid'!U32:W32} -> Player 1 | E32: 0 | F32: 0 | G32: {='Knockout Grid'!U33:W33} -> Player 32 | H32: 0 | I32: 0

Sheet Knockout Grid
A1: 1 | B1: 32 | C1: 1
A2: G1W
A3: bye | F3: 17 | G3: 16 | H3: 1
F4: G1W
A5: 2 | B5: 32 | C5: 2 | F5: Player 4
A6: Player 3
A7: Player 4 | K7: 25 | L7: Q | M7: 1
K8: Player 1
A9: 3 | B9: 32 | C9: 3 | K9: Player 8
A10: Player 5
A11: Player 6 | F11: 18 | G11: 16 | H11: 2
F12: Player 5
A13: 4 | B13: 32 | C13: 4 | F13: Player 8
A14: Player 7
A15: Player 8 | P15: 29 | Q15: S | R15: 1
P16: Player 1
A17: 5 | B17: 32 | C17: 5 | P17: Player 16
A18: Player 9
A19: Player 10 | F19: 19 | G19: 16 | H19: 3
F20: Player 9
A21: 6 | B21: 32 | C21: 6 | F21: Player 12
A22: Player 11
A23: Player 12 | K23: 26 | L23: Q | M23: 2
K24: Player 9
A25: 7 | B25: 32 | C25: 7 | K25: Player 16
A26: Player 13
A27: Player 14 | F27: 20 | G27: 16 | H27: 4
F28: Player 13
A29: 8 | B29: 32 | C29: 8 | F29: Player 16
A30: bye
A31: Player 16 | U31: 31 | V31: F | W31: 1
U32: Player 1
A33: 9 | B33: 32 | C33: 9 | U33: Player 32
A34: Player 17
A35: bye | F35: 21 | G35: 16 | H35: 5
F36: Player 17
A37: 10 | B37: 32 | C37: 10 | F37: Player 20
A38: Player 19
A39: Player 20 | K39: 27 | L39: Q | M39: 3
K40: Player 17
...
